<?xml version="1.0"?>
<robot name="biped_s70_upper_body">
  <!-- 由 scripts/extract-upper-body-urdf.mjs 从 biped_s70.urdf 自动生成：仅保留 base_link、躯干与双臂 -->
  <link name="world"/>
  <joint name="world_to_base" type="fixed">
    <parent link="world"/>
    <child link="base_link"/>
    <origin xyz="0 0 0" rpy="0 0 0"/>
  </joint>
<link name="base_link">
    <visual>
      <origin xyz="0 0 0" rpy="0 0 0" />
      <geometry>
        <mesh filename="../meshes/base_link.STL" />
      </geometry>
      <material name="base_link_mat">
        <color rgba="0.89804314 0.91372941 0.92549412 1.00000000"/>
      </material>
    </visual>
    <collision>
      <origin xyz="0.0003142 0.000886 -0.0510539" rpy="1.5707963 0 0" />
      <geometry>
        <cylinder radius="0.09345" length="0.04711" />
      </geometry>
    </collision>
    <inertial>
      <origin xyz="-0.0001312 0 -0.0325845" rpy="0 0 0" />
      <mass value="1.765034" />
      <inertia ixx="0.0051749" ixy="0" ixz="0.0000127" iyy="0.0087755" iyz="0" izz="0.006817"/></inertial>
  </link>

<link name="waist_yaw">
    <visual>
      <origin xyz="0 0 0" rpy="0 0 0" />
      <geometry>
        <mesh filename="meshes/waist_yaw.STL" />
      </geometry>
      <material name="waist_yaw_mat">
        <color rgba="1.00000000 1.00000000 1.00000000 1.00000000"/>
      </material>
    </visual>
    <inertial>
      <origin xyz="0.0012045 0.0000454 0.0626676" rpy="0 0 0" />
      <mass value="5.4706791" />
      <inertia ixx="0.030755" ixy="0.0000211" ixz="-0.0004428" iyy="0.0168136" iyz="-0.0000229" izz="0.0237983"/></inertial>
  </link>

<link name="waist_l_bar">
    <visual>
      <origin xyz="0 0 0" rpy="0 0 0" />
      <geometry>
        <mesh filename="../meshes/waist_l_bar.STL" />
      </geometry>
    </visual>
    <inertial>
      <origin xyz="-0.0155887 0.0189118 -0.005698" rpy="0 0 0" />
      <mass value="0.14009" />
      <inertia ixx="0.0000334" ixy="-0.0000109" ixz="-0.0000196" iyy="0.0001007" iyz="-0.000004" izz="0.0000798"/></inertial>
  </link>

<link name="waist_l_bar_tendon">
    <visual>
      <origin xyz="0 0 0" rpy="0 0 0" />
      <geometry>
        <mesh filename="../meshes/waist_l_bar_tendon.STL" />
      </geometry>
    </visual>
    <inertial>
      <origin xyz="-0.0026943 0.0004796 0.0260108" rpy="0 0 0" />
      <mass value="0.0872416" />
      <inertia ixx="0.0000484" ixy="0" ixz="0.0000044" iyy="0.0000542" iyz="0" izz="0.0000067"/></inertial>
  </link>

<link name="waist_r_bar">
    <visual>
      <origin xyz="0 0 0" rpy="0 0 0" />
      <geometry>
        <mesh filename="../meshes/waist_r_bar.STL" />
      </geometry>
    </visual>
    <inertial>
      <origin xyz="-0.0155887 -0.0189118 -0.0056979" rpy="0 0 0" />
      <mass value="0.14009" />
      <inertia ixx="0.0000334" ixy="0.0000109" ixz="-0.0000196" iyy="0.0001007" iyz="0.000004" izz="0.0000798"/></inertial>
  </link>

<link name="waist_r_bar_tendon">
    <visual>
      <origin xyz="0 0 0" rpy="0 0 0" />
      <geometry>
        <mesh filename="../meshes/waist_r_bar_tendon.STL" />
      </geometry>
    </visual>
    <inertial>
      <origin xyz="-0.0026911 -0.0004795 0.0260112" rpy="0 0 0" />
      <mass value="0.0872416" />
      <inertia ixx="0.0000484" ixy="0" ixz="0.0000044" iyy="0.0000542" iyz="0" izz="0.0000067"/></inertial>
  </link>

<link name="waist_pitch">
    <visual>
      <origin xyz="0 0 0" rpy="0 0 0" />
      <geometry>
        <mesh filename="../meshes/waist_pitch.STL" />
      </geometry>
      <material name="waist_pitch_mat">
        <color rgba="0.89804314 0.91372941 0.92549412 1.00000000"/>
      </material>
    </visual>
    <inertial>
      <origin xyz="0 0 -0.0085519" rpy="0 0 0" />
      <mass value="0.5291876" />
      <inertia ixx="0.0003269" ixy="0" ixz="0" iyy="0.0001757" iyz="0" izz="0.0003542"/></inertial>
  </link>

<link name="waist_roll">
    <visual>
      <origin xyz="0 0 0" rpy="0 0 0" />
      <geometry>
        <mesh filename="../meshes/waist_roll.STL" />
      </geometry>
      <material name="waist_roll_mat">
        <color rgba="0.79216078 0.81961176 0.92941569 1.00000000"/>
      </material>
    </visual>
    <collision>
      <origin xyz="-0.0329227 -0.0005721 0.17882" rpy="0 0 0" />
      <geometry>
        <capsule radius="0.11656" length="0.24162" />
      </geometry>
    </collision>
    <inertial>
      <origin xyz="-0.043151 -0.0018019 0.1491034" rpy="0 0 0" />
      <mass value="8.2475928" />
      <inertia ixx="0.0870365" ixy="0.000146" ixz="-0.0007178" iyy="0.074102" iyz="0.0003701" izz="0.0550014"/></inertial>
  </link>

<link name="torso">
    <inertial>
      <origin xyz="0 0 0" rpy="0 0 0" />
      <mass value="2.6635" />
      <inertia ixx="0.001" ixy="0" ixz="0" iyy="0.001" iyz="0" izz="0.001"/></inertial>
  </link>

<link name="l_arm_base">
    <visual>
      <origin xyz="0 0 0" rpy="0 0 0" />
      <geometry>
        <mesh filename="../meshes/L_arm_base.STL" />
      </geometry>
      <material name="l_arm_base_mat">
        <color rgba="1.00000000 1.00000000 1.00000000 1.00000000"/>
      </material>
    </visual>
    
    <inertial>
      <origin xyz="0.0001806 0.0339966 0.0000349" rpy="0 0 0" />
      <mass value="0.1821772" />
      <inertia ixx="0.0002488" ixy="0.0000011" ixz="0.0000007" iyy="0.0003393" iyz="0.0000013" izz="0.0002463"/></inertial>
  </link>

<link name="zarm_l1_link">
    <visual>
      <origin xyz="0 0 0" rpy="0 0 0" />
      <geometry>
        <mesh filename="../meshes/L_arm_pitch.STL" />
      </geometry>
      <material name="zarm_l1_link_mat">
        <color rgba="1.00000000 1.00000000 1.00000000 1.00000000"/>
      </material>
    </visual>
    <collision>
      <origin xyz="-0.0005 0.069875 0" rpy="-1.5707963 0 0" />
      <geometry>
        <cylinder radius="0.04863" length="0.0415" />
      </geometry>
    </collision>
    <inertial>
      <origin xyz="0.0012213 0.0733264 0.0000059" rpy="0 0 0" />
      <mass value="0.2633409" />
      <inertia ixx="0.0004071" ixy="0.0000352" ixz="0" iyy="0.0002516" iyz="0" izz="0.0003111"/></inertial>
  </link>

<link name="zarm_l2_link">
    <visual>
      <origin xyz="0 0 0" rpy="0 0 0" />
      <geometry>
        <mesh filename="../meshes/L_arm_roll.STL" />
      </geometry>
      <material name="zarm_l2_link_mat">
        <color rgba="1.00000000 1.00000000 1.00000000 1.00000000"/>
      </material>
    </visual>
    <collision>
      <origin xyz="0 0 0" rpy="0 -1.5707963 0" />
      <geometry>
        <cylinder radius="0.05" length="0.1175" />
      </geometry>
    </collision>
    <inertial>
      <origin xyz="-0.00070214 -0.00000601 -0.04627791" rpy="0 0 0" />
      <mass value="0.43789" />
      <inertia ixx="0.00088092" ixy="0.00000011" ixz="-0.00002250" iyy="0.00128467" iyz="0.00000014" izz="0.00077467"/></inertial>
  </link>

<link name="zarm_l3_link">
    <visual>
      <origin xyz="0 0 0" rpy="0 0 0" />
      <geometry>
        <mesh filename="../meshes/L_arm_yaw.STL" />
      </geometry>
      <material name="zarm_l3_link_mat">
        <color rgba="1.00000000 1.00000000 1.00000000 1.00000000"/>
      </material>
    </visual>
    <collision>
      <origin xyz="0 0 -0.18" rpy="0 0 0" />
      <geometry>
        <capsule radius="0.045" length="0.14" />
      </geometry>
    </collision>
    <collision>
      <origin xyz="0.01 0 -0.28" rpy="-1.5707963 0 0" />
      <geometry>
        <cylinder radius="0.05" length="0.0875" />
      </geometry>
    </collision>
    <inertial>
      <origin xyz="0.00964741 0.00319323 -0.22919475" rpy="0 0 0" />
      <mass value="1.83545" />
      <inertia ixx="0.00729083" ixy="-0.00007288" ixz="0.00081125" iyy="0.00738284" iyz="0.00031695" izz="0.00195142"/></inertial>
  </link>

<link name="zarm_l4_link">
    <visual>
      <origin xyz="0 0 0" rpy="0 0 0" />
      <geometry>
        <mesh filename="../meshes/L_forearm.STL" />
      </geometry>
      <material name="zarm_l4_link_mat">
        <color rgba="1.00000000 1.00000000 1.00000000 1.00000000"/>
      </material>
    </visual>
    <collision>
      <origin xyz="-0.02 0 -0.14" rpy="0 0 0" />
      <geometry>
        <capsule radius="0.045" length="0.18" />
      </geometry>
    </collision>
    <inertial>
      <origin xyz="-0.01826291 0.00208235 -0.06695837" rpy="0 0 0" />
      <mass value="0.65770" />
      <inertia ixx="0.00155516" ixy="-0.00001090" ixz="-0.00013674" iyy="0.00134001" iyz="-0.00005219" izz="0.00071369"/></inertial>
  </link>

<link name="zarm_l5_link">
    <visual>
      <origin xyz="0 0 0" rpy="0 0 0" />
      <geometry>
        <mesh filename="../meshes/L_hand_yaw.STL" />
      </geometry>
      <material name="zarm_l5_link_mat">
        <color rgba="1.00000000 1.00000000 1.00000000 1.00000000"/>
      </material>
    </visual>
    <inertial>
      <origin xyz="-0.00889277 0.00001406 -0.05689638" rpy="0 0 0" />
      <mass value="0.67878" />
      <inertia ixx="0.00070608" ixy="0.00000004" ixz="-0.00006375" iyy="0.00105527" iyz="-0.00000153" izz="0.00059293"/></inertial>
  </link>

<link name="zarm_l6_link">
    <visual>
      <origin xyz="0 0 0" rpy="0 0 0" />
      <geometry>
        <mesh filename="../meshes/L_hand_roll.STL" />
      </geometry>
      <material name="zarm_l6_link_mat">
        <color rgba="0.89804314 0.91372941 0.92549412 1.00000000"/>
      </material>
    </visual>
    <inertial>
      <origin xyz="-0.00174110 0.00664955 -0.01430084" rpy="0 0 0" />
      <mass value="0.51231" />
      <inertia ixx="0.00019781" ixy="-0.00000521" ixz="0.00001293" iyy="0.00030102" iyz="0.00001207" izz="0.00030567"/></inertial>
  </link>

<link name="zarm_l7_link">
    <visual>
      <origin xyz="0 0 0" rpy="0 0 0" />
      <geometry>
        <mesh filename="../meshes/L_hand_pitch_nohand.STL" />
      </geometry>
      <material name="zarm_l7_link_mat">
        <color rgba="1.00000000 1.00000000 1.00000000 1.00000000"/>
      </material>
    </visual>
    <collision>
      <origin xyz="0 0 -0.158" rpy="0 0 -3.1415" />
      <geometry>
        <box size="0.08 0.05 0.16" />
      </geometry>
    </collision>
    <collision>
      <origin xyz="0.0505 -0.0292 -0.116372" rpy="0 -0.2545 0" />
      <geometry>
        <cylinder radius="0.01" length="0.08" />
      </geometry>
    </collision>
    <inertial>
      <origin xyz="0.00481393 0.00873606 -0.0837543" rpy="0 0 0" />
      <mass value="0.7374" />
      <inertia ixx="0.00112502" ixy="0" ixz="0" iyy="0.00133239" iyz="0" izz="0.000373427"/></inertial>
  </link>

<link name="L_foream_Prismatic_link">
    <visual>
      <origin xyz="0 0 0" rpy="0 0 0" />
      <geometry>
        <mesh filename="../meshes/L_foream_Prismatic_link.STL" />
      </geometry>
    </visual>
    <inertial>
      <origin xyz="0 0.0000001 0.0589941" rpy="0 0 0" />
      <mass value="0.017315" />
      <inertia ixx="0.0000235" ixy="0" ixz="0" iyy="0.0000236" iyz="0" izz="0.0000007"/></inertial>
  </link>

<link name="L_foream_input_link">
    <visual>
      <origin xyz="0 0 0" rpy="0 0 0" />
      <geometry>
        <mesh filename="../meshes/L_foream_input_link.STL" />
      </geometry>
    </visual>
    <inertial>
      <origin xyz="-0.003105 0.0002455 -0.0226535" rpy="0 0 0" />
      <mass value="0.0149783" />
      <inertia ixx="0.0000033" ixy="0" ixz="-0.0000001" iyy="0.0000032" iyz="0" izz="0.000001"/></inertial>
  </link>

<link name="zarm_l7_end_effector">
    <collision>
      <origin xyz="0 0 0" rpy="0 0 0" />
      <geometry>
        <sphere radius="0.005" />
      </geometry>
    </collision>
  </link>

<link name="r_arm_base">
    <visual>
      <origin xyz="0 0 0" rpy="0 0 0" />
      <geometry>
        <mesh filename="../meshes/R_arm_base.STL" />
      </geometry>
      <material name="r_arm_base_mat">
        <color rgba="1.00000000 1.00000000 1.00000000 1.00000000"/>
      </material>
    </visual>
    <inertial>
      <origin xyz="0.0001806 -0.0339966 0.0000349" rpy="0 0 0" />
      <mass value="0.1821772" />
      <inertia ixx="0.0002488" ixy="-0.0000011" ixz="0.0000007" iyy="0.0003393" iyz="-0.0000013" izz="0.0002463"/></inertial>
  </link>

<link name="zarm_r1_link">
    <visual>
      <origin xyz="0 0 0" rpy="0 0 0" />
      <geometry>
        <mesh filename="../meshes/R_arm_pitch.STL" />
      </geometry>
      <material name="zarm_r1_link_mat">
        <color rgba="1.00000000 1.00000000 1.00000000 1.00000000"/>
      </material>
    </visual>
    <collision>
      <origin xyz="-0.0005 -0.069875 0" rpy="-1.5707963 0 0" />
      <geometry>
        <cylinder radius="0.04863" length="0.0415" />
      </geometry>
    </collision>
    <inertial>
      <origin xyz="0.0012213 -0.0733264 0.0000059" rpy="0 0 0" />
      <mass value="0.2633409" />
      <inertia ixx="0.0004071" ixy="-0.0000352" ixz="0" iyy="0.0002516" iyz="0" izz="0.0003111"/></inertial>
  </link>

<link name="zarm_r2_link">
    <visual>
      <origin xyz="0 0 0" rpy="0 0 0" />
      <geometry>
        <mesh filename="../meshes/R_arm_roll.STL" />
      </geometry>
      <material name="zarm_r2_link_mat">
        <color rgba="1.00000000 1.00000000 1.00000000 1.00000000"/>
      </material>
    </visual>
    <collision>
      <origin xyz="0 0 0" rpy="0 -1.5707963 0" />
      <geometry>
        <cylinder radius="0.05" length="0.1175" />
      </geometry>
    </collision>
    <inertial>
      <origin xyz="-0.00070214 0.00000601 -0.04627791" rpy="0 0 0" />
      <mass value="0.43789" />
      <inertia ixx="0.00088092" ixy="-0.00000011" ixz="-0.00002250" iyy="0.00128467" iyz="-0.00000014" izz="0.00077467"/></inertial>
  </link>

<link name="zarm_r3_link">
    <visual>
      <origin xyz="0 0 0" rpy="0 0 0" />
      <geometry>
        <mesh filename="../meshes/R_arm_yaw.STL" />
      </geometry>
      <material name="zarm_r3_link_mat">
        <color rgba="1.00000000 1.00000000 1.00000000 1.00000000"/>
      </material>
    </visual>
    <collision>
      <origin xyz="0 0 -0.18" rpy="0 0 0" />
      <geometry>
        <capsule radius="0.045" length="0.14" />
      </geometry>
    </collision>
    <collision>
      <origin xyz="0.01 0 -0.28" rpy="-1.5707963 0 0" />
      <geometry>
        <cylinder radius="0.05" length="0.0875" />
      </geometry>
    </collision>
    <inertial>
      <origin xyz="0.00964741 -0.00319323 -0.22919475" rpy="0 0 0" />
      <mass value="1.83545" />
      <inertia ixx="0.00729083" ixy="0.00007288" ixz="0.00081125" iyy="0.00738284" iyz="-0.00031695" izz="0.00195142"/></inertial>
  </link>

<link name="zarm_r4_link">
    <visual>
      <origin xyz="0 0 0" rpy="0 0 0" />
      <geometry>
        <mesh filename="../meshes/R_forearm.STL" />
      </geometry>
      <material name="zarm_r4_link_mat">
        <color rgba="1.00000000 1.00000000 1.00000000 1.00000000"/>
      </material>
    </visual>
    <collision>
      <origin xyz="-0.02 0 -0.14" rpy="0 0 0" />
      <geometry>
        <capsule radius="0.045" length="0.18" />
      </geometry>
    </collision>
    <inertial>
      <origin xyz="-0.01826291 -0.00208235 -0.06695837" rpy="0 0 0" />
      <mass value="0.65770" />
      <inertia ixx="0.00155516" ixy="0.00001090" ixz="-0.00013674" iyy="0.00134001" iyz="0.00005219" izz="0.00071369"/></inertial>
  </link>

<link name="zarm_r5_link">
    <visual>
      <origin xyz="0 0 0" rpy="0 0 0" />
      <geometry>
        <mesh filename="../meshes/R_hand_yaw.STL" />
      </geometry>
      <material name="zarm_r5_link_mat">
        <color rgba="1.00000000 1.00000000 1.00000000 1.00000000"/>
      </material>
    </visual>
    <inertial>
      <origin xyz="-0.00889277 -0.00001406 -0.05689638" rpy="0 0 0" />
      <mass value="0.67878" />
      <inertia ixx="0.00070608" ixy="-0.00000004" ixz="-0.00006375" iyy="0.00105527" iyz="0.00000153" izz="0.00059293"/></inertial>
  </link>

<link name="zarm_r6_link">
    <visual>
      <origin xyz="0 0 0" rpy="0 0 0" />
      <geometry>
        <mesh filename="../meshes/R_hand_roll.STL" />
      </geometry>
      <material name="zarm_r6_link_mat">
        <color rgba="0.89804314 0.91372941 0.92549412 1.00000000"/>
      </material>
    </visual>
    <inertial>
      <origin xyz="-0.00174110 -0.00664955 -0.01430084" rpy="0 0 0" />
      <mass value="0.51231" />
      <inertia ixx="0.00019781" ixy="0.00000521" ixz="0.00001293" iyy="0.00030102" iyz="-0.00001207" izz="0.00030567"/></inertial>
  </link>

<link name="zarm_r7_link">
    <visual>
      <origin xyz="0 0 0" rpy="0 0 0" />
      <geometry>
        <mesh filename="../meshes/R_hand_pitch_nohand.STL" />
      </geometry>
      <material name="zarm_r7_link_mat">
        <color rgba="1.00000000 1.00000000 1.00000000 1.00000000"/>
      </material>
    </visual>
    <collision>
      <origin xyz="0 0 -0.158" rpy="0 0 -3.1415" />
      <geometry>
        <box size="0.08 0.05 0.16" />
      </geometry>
    </collision>
    <collision>
      <origin xyz="0.0505 0.0292 -0.116372" rpy="0 -0.2545 0" />
      <geometry>
        <cylinder radius="0.01" length="0.08" />
      </geometry>
    </collision>
    <inertial>
      <origin xyz="0.00481393 -0.00870857 -0.0836411" rpy="0 0 0" />
      <mass value="0.7374" />
      <inertia ixx="0.00110836" ixy="0" ixz="0" iyy="0.00131607" iyz="0" izz="0.000374168"/></inertial>
  </link>

<link name="R_foream_Prismatic_link">
    <visual>
      <origin xyz="0 0 0" rpy="0 0 0" />
      <geometry>
        <mesh filename="../meshes/R_foream_Prismatic_link.STL" />
      </geometry>
    </visual>
    <inertial>
      <origin xyz="0 -0.0000001 0.0589941" rpy="0 0 0" />
      <mass value="0.017315" />
      <inertia ixx="0.0000235" ixy="0" ixz="0" iyy="0.0000236" iyz="0" izz="0.0000007"/></inertial>
  </link>

<link name="R_foream_input_link">
    <visual>
      <origin xyz="0 0 0" rpy="0 0 0" />
      <geometry>
        <mesh filename="../meshes/R_foream_input_link.STL" />
      </geometry>
    </visual>
    <inertial>
      <origin xyz="-0.003105 -0.0002455 -0.0226535" rpy="0 0 0" />
      <mass value="0.0149783" />
      <inertia ixx="0.0000033" ixy="0" ixz="-0.0000001" iyy="0.0000032" iyz="0" izz="0.000001"/></inertial>
  </link>

<link name="zarm_r7_end_effector">
    <collision>
      <origin xyz="0 0 0" rpy="0 0 0" />
      <geometry>
        <sphere radius="0.005" />
      </geometry>
    </collision>
  </link>

<joint name="waist_yaw_joint" type="revolute">
    <parent link="base_link" />
    <child link="waist_yaw" />
    <origin xyz="0 0 0.03" rpy="0 0 0" />
    <axis xyz="0 0 1" />
    <limit lower="-2.70526" upper="2.70526" effort="1000" velocity="10" />
  </joint>

<joint name="waist_l_bar_joint" type="fixed">
    <parent link="waist_yaw" />
    <child link="waist_l_bar" />
    <origin xyz="0 0.026 0.11123" rpy="0 0 0" />
    <axis xyz="0 1 0" />
    <limit lower="-3.14159" upper="3.14159" effort="1000" velocity="10" />
  </joint>

<joint name="waist_l_bar_tendon_joint" type="fixed">
    <parent link="waist_l_bar" />
    <child link="waist_l_bar_tendon" />
    <origin xyz="-0.04884 0 -0.017852" rpy="0 0 0" />
    <axis xyz="0 1 0" />
    <limit lower="-3.14159" upper="3.14159" effort="1000" velocity="10" />
  </joint>

<joint name="waist_r_bar_joint" type="fixed">
    <parent link="waist_yaw" />
    <child link="waist_r_bar" />
    <origin xyz="0 -0.026 0.11123" rpy="0 0 0" />
    <axis xyz="0 1 0" />
    <limit lower="-3.14159" upper="3.14159" effort="1000" velocity="10" />
  </joint>

<joint name="waist_r_bar_tendon_joint" type="fixed">
    <parent link="waist_r_bar" />
    <child link="waist_r_bar_tendon" />
    <origin xyz="-0.04884 0 -0.017852" rpy="0 0 0" />
    <axis xyz="0 1 0" />
    <limit lower="-3.14159" upper="3.14159" effort="1000" velocity="10" />
  </joint>

<joint name="waist_pitch_joint" type="revolute">
    <parent link="waist_yaw" />
    <child link="waist_pitch" />
    <origin xyz="0.03677 0 0.148" rpy="0 0 0" />
    <axis xyz="0 1 0" />
    <limit lower="-0.261799" upper="0.523599" effort="1000" velocity="10" />
  </joint>

<joint name="waist_roll_joint" type="revolute">
    <parent link="waist_pitch" />
    <child link="waist_roll" />
    <origin xyz="0 0 -0.023" rpy="0 0 0" />
    <axis xyz="1 0 0" />
    <limit lower="-0.261799" upper="0.261799" effort="1000" velocity="10" />
  </joint>

<joint name="torso_joint" type="fixed">
    <parent link="waist_roll" />
    <child link="torso" />
    <origin xyz="0 0 0" rpy="0 0 0" />
  </joint>

<joint name="l_arm_base_joint" type="fixed">
    <parent link="waist_roll" />
    <child link="l_arm_base" />
    <origin xyz="-0.03677 0.108 0.2285" rpy="0 0 0" />
  </joint>

<joint name="zarm_l1_joint" type="revolute">
    <parent link="l_arm_base" />
    <child link="zarm_l1_link" />
    <origin xyz="0.0001839 0.06075 0.0000493" rpy="0 0 0" />
    <axis xyz="0 1 0" />
    <limit lower="-3.141593" upper="1.570796" effort="1000" velocity="10" />
  </joint>

<joint name="zarm_l2_joint" type="revolute">
    <parent link="zarm_l1_link" />
    <child link="zarm_l2_link" />
    <origin xyz="0 0.08825 0" rpy="0 0 0" />
    <axis xyz="1 0 0" />
    <limit lower="-0.349065850398866" upper="3.49065850398866" effort="75.0" velocity="8.0" />
  </joint>

<joint name="zarm_l3_joint" type="revolute">
    <parent link="zarm_l2_link" />
    <child link="zarm_l3_link" />
    <origin xyz="0 0 0" rpy="0 0 0" />
    <axis xyz="0 0 1" />
    <limit lower="-1.48352986419518" upper="1.48352986419518" effort="57.0" velocity="7.5" />
  </joint>

<joint name="zarm_l4_joint" type="revolute">
    <parent link="zarm_l3_link" />
    <child link="zarm_l4_link" />
    <origin xyz="0.02 0 -0.2837" rpy="0 0 0" />
    <axis xyz="0 1 0" />
    <limit lower="-2.61799387799149" upper="0.0" effort="75.0" velocity="8.0" />
  </joint>

<joint name="zarm_l5_joint" type="revolute">
    <parent link="zarm_l4_link" />
    <child link="zarm_l5_link" />
    <origin xyz="-0.02 0 -0.1201" rpy="0 0 0" />
    <axis xyz="0 0 1" />
    <limit lower="-1.5707963267949" upper="1.5707963267949" effort="14.1" velocity="17.5" />
  </joint>

<joint name="zarm_l6_joint" type="revolute">
    <parent link="zarm_l5_link" />
    <child link="zarm_l6_link" />
    <origin xyz="0 0 -0.114" rpy="0 0 0" />
    <axis xyz="1 0 0" />
    <limit lower="-1.30899693899575" upper="0.698131700797732" effort="14.1" velocity="17.5" />
  </joint>

<joint name="zarm_l7_joint" type="revolute">
    <parent link="zarm_l6_link" />
    <child link="zarm_l7_link" />
    <origin xyz="0 0 -0.021" rpy="0 0 0" />
    <axis xyz="0 1 0" />
    <limit lower="-0.698131700797732" upper="0.698131700797732" effort="14.1" velocity="17.5" />
  </joint>

<joint name="L_foream_Prismatic_joint" type="fixed">
    <parent link="zarm_l3_link" />
    <child link="L_foream_Prismatic_link" />
    <origin xyz="0 0 -0.22077" rpy="0 0 0" />
  </joint>

<joint name="L_foream_input_joint" type="fixed">
    <parent link="L_foream_Prismatic_link" />
    <child link="L_foream_input_link" />
    <origin xyz="0 0 0" rpy="0 0 0" />
  </joint>

<joint name="zarm_l7_end_effector_joint" type="fixed">
    <parent link="zarm_l7_link" />
    <child link="zarm_l7_end_effector" />
    <origin xyz="0 0 -0.17" rpy="0 0 0" />
  </joint>

<joint name="r_arm_base_joint" type="fixed">
    <parent link="waist_roll" />
    <child link="r_arm_base" />
    <origin xyz="-0.03677 -0.108 0.2285" rpy="0 0 0" />
  </joint>

<joint name="zarm_r1_joint" type="revolute">
    <parent link="r_arm_base" />
    <child link="zarm_r1_link" />
    <origin xyz="0.0001839 -0.06075 0.0000493" rpy="0 0 0" />
    <axis xyz="0 1 0" />
    <limit lower="-3.141593" upper="1.570796" effort="1000" velocity="10" />
  </joint>

<joint name="zarm_r2_joint" type="revolute">
    <parent link="zarm_r1_link" />
    <child link="zarm_r2_link" />
    <origin xyz="0 -0.08825 0" rpy="0 0 0" />
    <axis xyz="1 0 0" />
    <limit lower="-3.49065850398866" upper="0.349065850398866" effort="75.0" velocity="8.0" />
  </joint>

<joint name="zarm_r3_joint" type="revolute">
    <parent link="zarm_r2_link" />
    <child link="zarm_r3_link" />
    <origin xyz="0 0 0" rpy="0 0 0" />
    <axis xyz="0 0 1" />
    <limit lower="-1.48352986419518" upper="1.48352986419518" effort="57.0" velocity="7.5" />
  </joint>

<joint name="zarm_r4_joint" type="revolute">
    <parent link="zarm_r3_link" />
    <child link="zarm_r4_link" />
    <origin xyz="0.02 0 -0.2837" rpy="0 0 0" />
    <axis xyz="0 1 0" />
    <limit lower="-2.61799387799149" upper="0.0" effort="75.0" velocity="8.0" />
  </joint>

<joint name="zarm_r5_joint" type="revolute">
    <parent link="zarm_r4_link" />
    <child link="zarm_r5_link" />
    <origin xyz="-0.02 0 -0.1201" rpy="0 0 0" />
    <axis xyz="0 0 1" />
    <limit lower="-1.5707963267949" upper="1.5707963267949" effort="14.1" velocity="17.5" />
  </joint>

<joint name="zarm_r6_joint" type="revolute">
    <parent link="zarm_r5_link" />
    <child link="zarm_r6_link" />
    <origin xyz="0 0 -0.114" rpy="0 0 0" />
    <axis xyz="1 0 0" />
    <limit lower="-0.698131700797732" upper="1.30899693899575" effort="14.1" velocity="17.5" />
  </joint>

<joint name="zarm_r7_joint" type="revolute">
    <parent link="zarm_r6_link" />
    <child link="zarm_r7_link" />
    <origin xyz="0 0 -0.021" rpy="0 0 0" />
    <axis xyz="0 1 0" />
    <limit lower="-0.698131700797732" upper="0.698131700797732" effort="14.1" velocity="17.5" />
  </joint>

<joint name="R_foream_Prismatic_joint" type="fixed">
    <parent link="zarm_r3_link" />
    <child link="R_foream_Prismatic_link" />
    <origin xyz="0 0 -0.22077" rpy="0 0 0" />
  </joint>

<joint name="R_foream_input_joint" type="fixed">
    <parent link="R_foream_Prismatic_link" />
    <child link="R_foream_input_link" />
    <origin xyz="0 0 0" rpy="0 0 0" />
  </joint>

<joint name="zarm_r7_end_effector_joint" type="fixed">
    <parent link="zarm_r7_link" />
    <child link="zarm_r7_end_effector" />
    <origin xyz="0 0 -0.17" rpy="0 0 0" />
  </joint>
</robot>
